<robot name="ExoskeletonURDFmodel">
<link name="ExoTorso">
	<inertial>
		<origin xyz="0.209727 -0.0253233 0.0806368" rpy="0 0 0"/>
		<mass value="3.456"/>
		<inertia ixx="0.0844668" ixy="-3.47676e-06" ixz="5.26495e-05" iyy="0.108439" iyz="-0.00845162" izz="0.0461007"/>
	</inertial>
	<visual>
		<origin xyz="0 0 0" rpy="0 0 0"/>
		<geometry>
			<mesh filename="package://Exoskeleton3DOF_URDFmodel/meshes/sim_torso_prt.stl" scale="0.001 0.001 0.001"/>
		</geometry>
		<material name="green">
			<color rgba="0 1 0 1"/>
		</material>
	</visual>
	<collision>
		<origin xyz="0 0 0" rpy="0 0 0"/>
		<geometry>
			<mesh filename="package://Exoskeleton3DOF_URDFmodel/meshes/sim_torso_prt.stl" scale="0.001 0.001 0.001"/>
		</geometry>
	</collision>
</link>

<link name="ExoRightLeg">
	<inertial>
		<origin xyz="-0.02912005 -0.0037811354695 -0.034212836698" rpy="0 0 0"/>
		<mass value="1.39397"/>
		<inertia ixx="0.0089399" ixy="0.000383612" ixz="0.00140254" iyy="0.00876079" iyz="-0.00120044" izz="0.00223467"/>
	</inertial>
	<visual>
		<origin xyz="0.00595245 0.147807000062 0.0825556000513" rpy="0 0 0"/>
		<geometry>
			<mesh filename="package://Exoskeleton3DOF_URDFmodel/meshes/sim_rightleg_prt.stl" scale="0.001 0.001 0.001"/>
		</geometry>
		<material name="black">
			<color rgba="0 0 0 1"/>
		</material>
	</visual>
	<collision>
		<origin xyz="0.00595245 0.147807000062 0.0825556000513" rpy="0 0 0"/>
		<geometry>
			<mesh filename="package://Exoskeleton3DOF_URDFmodel/meshes/sim_rightleg_prt.stl" scale="0.001 0.001 0.001"/>
		</geometry>
	</collision>
</link>

<link name="ExoLeftLeg">
	<inertial>
		<origin xyz="0.025847 -0.00274416217852 -0.0319784622128" rpy="0 0 0"/>
		<mass value="1.6863"/>
		<inertia ixx="0.0103787" ixy="-0.000357087" ixz="-0.001288" iyy="0.0100611" iyz="-0.00125274" izz="0.00258313"/>
	</inertial>
	<visual>
		<origin xyz="-0.425543 0.147807000204 0.0825556002785" rpy="0 0 0"/>
		<geometry>
			<mesh filename="package://Exoskeleton3DOF_URDFmodel/meshes/sim_leftleg_prt.stl" scale="0.001 0.001 0.001"/>
		</geometry>
		<material name="red">
			<color rgba="1 0 0 1"/>
		</material>
	</visual>
	<collision>
		<origin xyz="-0.425543 0.147807000204 0.0825556002785" rpy="0 0 0"/>
		<geometry>
			<mesh filename="package://Exoskeleton3DOF_URDFmodel/meshes/sim_leftleg_prt.stl" scale="0.001 0.001 0.001"/>
		</geometry>
	</collision>
	</link>

<!-- joints exoskeloton-human
	<joint name="jFixedExoskeleton" type="fixed"> 
		<origin xyz="-0.0670 0 0.03" rpy="0 0 1.5708"/>
		<parent link="T8"/>
		<child link="ExoTorso"/>
	</joint>
--> 

<!-- joints exoskelton hips -->
	<joint name="jActuatedRightHip_rotx" type="revolute">
		<origin xyz="-0.00595245 -0.147807 -0.0825556" rpy="0.18 0 0"/>
		<axis xyz="1.0 0.0 0.0"/>
		<parent link="ExoTorso"/>
		<child link="ExoRightLeg"/>
		<limit effort="50000" lower="-0.261799387799" upper="2.09439510239" velocity="50000"/>
		<dynamics damping="0.223"/>
	</joint>

	<joint name="jActuatedLeftHip_rotx" type="revolute">
		<origin xyz="0.425543 -0.147807 -0.0825556" rpy="0.18 0 0"/>
		<axis xyz="-1.0 0.0 0.0"/>
		<parent link="ExoTorso"/>
		<child link="ExoLeftLeg"/>
		<limit effort="50000" lower="-0.261799387799" upper="2.09439510239" velocity="50000"/>
		<dynamics damping="0.223"/>
	</joint>

</robot>

